Workbook

Sheet Formula Perros
B5: Formula cálculo Kcal/dia | D5: Fórmula cálculo Gr producto / dia
B6: FACTESTERILIZADO*FACTSNACKS*FACTOREDAD*(VAR-ACTIVIDAD*(PESO)^0,75) | D6: (Kcal/dia)/(kcal Em/kg de pienso)*1000
B10: Edad y tamaño de raza | C10: FACTOREDAD
B11: Raza S/M + Edad: Cachorro + Hasta 4 meses | C11: 2 | G11: Kcal/dia | H11: =C33*C38*C17*(C27*C39^0.75) -> 2479.3522
B12: Raza S/M + Edad: Cachorro + 4-6 meses | C12: 1.6
B13: Raza S/M + Edad: Cachorro + 6-10 meses | C13: 1.2
B14: Raza S/M + Edad: Cachorro + 10-12 meses | C14: 1
B15: Raza L + Edad: Cachorro Grande - Hasta 4 meses | C15: 2
B16: Raza L + Edad: Cachorro Grande - 4 - 8meses | C16: 1.6
B17: Raza L + Edad: Cachorro Grande - 8-12 meses | C17: 1.4
B18: Raza L + Edad: Cachorro Grande - 12 - 18 meses | C18: 1.2
B19: Raza L + Edad: Cachorro Grande - 18 - 24 meses | C19: 1
B20: Edad: Adulto | C20: 1
B21: Edad: Senior | C21: 0.8
B22: Edad: Adulto Raza Gigante | C22: 1.5
B24: Nivel de actividad | C24: VAR-ACTIVIDAD
B25: Adulto - Baja | C25: 95
B26: Adulto - Media | C26: 130
B27: Adulto - Muy alta (actividad deportiva) | C27: 180
B28: Cachorro | C28: 130
B29: Senior | C29: 130
B31: Esterilizado | C31: FACTESTERILIZADO
B32: Si | C32: 0.9
B33: No | C33: 1
B35: Premios | C35: FACTSNACKS
B36: 1 o menos al día | C36: 1
B37: 2-3 al día | C37: 0.9
B38: Más de 3 | C38: 0.88
B39: Peso | C39: 25

Sheet Formula Gatos
C5: Formula cálculo Kcal/dia | D5: Fórmula cáculo Gr producto / dia
C6: FACT*(PESO^FACT2) | D6: (Kcal/dia)/(kcal Em/kg de pienso)*1000
C10: Casos - Factores de la fórmula | D10: FACT | E10: FACT2
C11: GATOS JÓVENES 6-20 SEMANAS | D11: 250 | E11: 1 | I11: =D16*(2^E16) -> 159.1073
C12: GATOS JÓVENES 4-7 MESES | D12: 130 | E12: 1
C13: GATOS JÓVENES 7-9 MESES | D13: 100 | E13: 1
C14: GATOS JÓVENES 9-12 MESES | D14: 80 | E14: 1
C15: GATOS JOVENES >12 MESES | D15: 60 | E15: 1
C16: GATOS ADULTOS | D16: 100 | E16: 0.67
C17: GATOS EXCESO DE PESO (O ESTERILIZADO) | D17: 130 | E17: 0.4
C18: GATOS SENIOR | D18: 45 | E18: 1

Sheet Productos
A5: ID | B5: EAN | C5: Cantidad | D5: SKU | E5: Nombre | F5: Tipo Alimento | G5: Tipo Animal | H5: Segmento | I5: kcal Em/kg | J5: LINK WEB
A6: 43289910542553 | B6: 8436540365361 | C6: 500 gr | D6: RET005000 | E6: RETORN PUPPY SALMON 500 GR - NEW | F6: Seco | G6: Perro | H6: Cachorros | I6: 3451 | J6: https://retorn.com/products/pienso-natural-cachorros-salmon?variant=43289910542553
A7: 42813746315481 | B7: 8436540364869 | C7: 3 kg | D7: RET00503 | E7: RETORN PUPPY SALMON 3 KG - NEW | F7: Seco | G7: Perro | H7: Cachorros | I7: 3451 | J7: https://retorn.com/products/pienso-natural-cachorros-salmon?variant=42813746315481
A8: 12167525924930 | B8: 8436540360533 | C8: 6 kg | D8: RET0051 | E8: RETORN PUPPY SALMON 6 KG | F8: Seco | G8: Perro | H8: Cachorros | I8: 3451 | J8: https://retorn.com/products/pienso-natural-cachorros-salmon?variant=12167525924930
A9: 12167525924930 | B9: 8436540360540 | C9: 12 kg | D9: RET0052 | E9: RETORN PUPPY SALMON 12 KG | F9: Seco | G9: Perro | H9: Cachorros | I9: 3451 | J9: https://retorn.com/products/pienso-natural-cachorros-salmon?_pos=1&_sid=9414974ed&_ss=r&variant=12167525924930
A10: 43289889013977 | B10: 8436540366009 | C10: 500 gr | D10: RET006500 | E10: RETORN LIGHT AND SENIOR 500 GR - NEW | F10: Seco | G10: Perro | H10: Senior Light | I10: 3453 | J10: https://retorn.com/products/pienso-natural-perros-light?variant=43289889013977
A11: 12167962591298 | B11: 8436540365071 | C11: 3 kg | D11: RET00603 | E11: RETORN ADULT LIGHT & SENIOR 3 KG - NEW | F11: Seco | G11: Perro | H11: Senior Light | I11: 3453 | J11: https://retorn.com/products/pienso-natural-perros-light?variant=12167962591298
A12: 12167962656834 | B12: 8436540360588 | C12: 12 kg | D12: RET0062 | E12: RETORN LIGHT AND SENIOR SALMON 12 KG | F12: Seco | G12: Perro | H12: Senior Light | I12: 3453 | J12: https://retorn.com/products/pienso-natural-perros-light?variant=12167962656834
A13: 12167962689602 | B13: 8436540360595 | C13: 20 kg | D13: RET0063 | E13: RETORN LIGHT AND SENIOR SALMON 20 KG | F13: Seco | G13: Perro | H13: Senior Light | I13: 3453 | J13: https://retorn.com/products/pienso-natural-perros-light?variant=12167962689602
A14: 43289754370265 | B14: 8436540365989 | C14: 500 gr | D14: RETAP500 | E14: RETORN ADULT POLLO 500 GR - NEW | F14: Seco | G14: Perro | H14: Adulto Pollo | I14: 3674 | J14: https://retorn.com/products/pienso-natural-perros-pollo?variant=43289754370265
A15: 12167859863618 | B15: 8436540364616 | C15: 3 kg | D15: RETAP03 | E15: RETORN ADULT POLLO 3 KG - NEW | F15: Seco | G15: Perro | H15: Adulto Pollo | I15: 3674 | J15: https://retorn.com/products/pienso-natural-perros-pollo?variant=12167859863618
A16: 42655252512985 | B16: 8436540364630 | C16: 12 kg | D16: RETAP12 | E16: RETORN ADULT POLLO 12 KG - NEW | F16: Seco | G16: Perro | H16: Adulto Pollo | I16: 3674 | J16: https://retorn.com/products/pienso-natural-perros-pollo?variant=42655252512985
A17: 42655252545753 | B17: 8436540365095 | C17: 20 kg | D17: RETAP20 | E17: RETORN ADULT POLLO 20 KG - NEW | F17: Seco | G17: Perro | H17: Adulto Pollo | I17: 3674 | J17: https://retorn.com/products/pienso-natural-perros-pollo?variant=42655252545753
... A48: 42037603762393 | B48: 18436540365047 | C48: 80 gr X 18 ud | D48: RET4529KC | E48: CAJA (18UD) RETORN LATAS GATO KITTEN POLLO 80 GR | F48: Humedo | G48: Gato | H48: Cachorros | I48: 871 | J48: https://retorn.com/products/comida-humeda-para-gatitos-de-pollo?variant=42037603762393
A49: 49479598047571 | B49: 18436540371253 | C49: 80 gr X 24 ud | E49: CAJA (24UD) RETORN LATAS GATO KITTEN POLLO 80 GR | F49: Humedo | G49: Gato | H49: Cachorros | I49: 871 | J49: https://retorn.com/products/comida-humeda-para-gatitos-de-pollo?variant=49479598047571
A50: 12632988188738 | B50: 8436540360106 | C50: 80 gr | D50: RET4529 | E50: RETORN LATAS GATO POLLO 80 GR | F50: Humedo | G50: Gato | H50: Pollo | I50: 971 | J50: https://retorn.com/products/comida-humeda-para-gatos-pollo?variant=12632988188738
A51: 14243705159746 | B51: 18436540360103 | C51: 80 gr X 18 ud | D51: RET4529C | E51: CAJA (18UD) RETORN LATAS GATO POLLO 80 GR | F51: Humedo | G51: Gato | H51: Pollo | I51: 971 | J51: https://retorn.com/products/comida-humeda-para-gatos-pollo?variant=14243705159746
A52: 49139872891219 | B52: 18436540371185 | C52: 80 gr X 24 ud | D52: RET4529C24 | E52: CAJA (24UD) RETORN LATAS GATO POLLO 80 GR | F52: Humedo | G52: Gato | H52: Pollo | I52: 971 | J52: https://retorn.com/products/comida-humeda-para-gatos-pollo?variant=49139872891219
A53: 12633061228610 | B53: 8436540360113 | C53: 80 gr | D53: RET4530 | E53: RETORN LATAS GATO POLLO CON CONEJO 80 GR | F53: Humedo | G53: Gato | H53: Pollo Conejo | I53: 943 | J53: https://retorn.com/products/comida-humeda-para-gatos-pollo-conejo?variant=12633061228610
A54: 14243707453506 | B54: 18436540360110 | C54: 80 gr X 18 ud | D54: RET4530C | E54: CAJA (18UD) RETORN LATAS GATO POLLO CON CONEJO 80 GR | F54: Humedo | G54: Gato | H54: Pollo Conejo | I54: 943 | J54: https://retorn.com/products/comida-humeda-para-gatos-pollo-conejo?variant=14243707453506
A55: 49139879051603 | B55: 18436540371192 | C55: 80 gr X 24 ud | D55: RET4530C24 | E55: CAJA (24UD) RETORN LATAS GATO POLLO CON CONEJO 80 GR | F55: Humedo | G55: Gato | H55: Pollo Conejo | I55: 943 | J55: https://retorn.com/products/comida-humeda-para-gatos-pollo-conejo?variant=49139879051603
A56: 12633070927938 | B56: 8436540360441 | C56: 80 gr | D56: RET4535 | E56: RETORN LATAS GATO ATUN CON MEJILLONES 80 GR | F56: Humedo | G56: Gato | H56: Mejillones | I56: 656 | J56: https://retorn.com/products/comida-humeda-para-gatos-atun-mejillones?variant=14243686580290
A57: 14243686580290 | B57: 18436540360448 | C57: 80 gr X 18 ud | D57: RET4535C | E57: CAJA (18UD) RETORN LATAS GATO ATUN CON MEJILLONES 80 GR | F57: Humedo | G57: Gato | H57: Mejillones | I57: 656 | J57: https://retorn.com/products/comida-humeda-para-gatos-atun-mejillones?variant=14243686580290
A58: 49139897893203 | B58: 18436540371222 | C58: 80 gr X 24 ud | D58: RET4535C24 | E58: CAJA (24UD) RETORN LATAS GATO ATUN CON MEJILLONES 80 GR | F58: Humedo | G58: Gato | H58: Mejillones | I58: 656 | J58: https://retorn.com/products/comida-humeda-para-gatos-atun-mejillones?variant=49139897893203
A59: 49139894681939 | B59: 8436540360434 | C59: 80 gr | D59: RET4536 | E59: RETORN LATAS GATO ATUN CON SARDINA 80 GR | F59: Humedo | G59: Gato | H59: Sardina | I59: 704 | J59: https://retorn.com/products/comida-humeda-gatos-atun-sardina?variant=12633132662850
A60: 14243698737218 | B60: 18436540360431 | C60: 80 gr X 18 ud | D60: RET4536C | E60: CAJA (18UD) RETORN LATAS GATO ATUN CON SARDINA 80 GR | F60: Humedo | G60: Gato | H60: Sardina | I60: 704 | J60: https://retorn.com/products/comida-humeda-gatos-atun-sardina?variant=14243698737218
A61: 49139894681939 | B61: 18436540371239 | C61: 80 gr X 24 ud | D61: RET4536C24 | E61: CAJA (24UD) RETORN LATAS GATO ATUN CON SARDINA 80 GR | F61: Humedo | G61: Gato | H61: Sardina | I61: 704 | J61: https://retorn.com/products/comida-humeda-gatos-atun-sardina?variant=49139894681939
... A66: 48155011350867 | B66: 18436540371246 | C66: 80 gr X 24 ud | D66: RET4538C24 | E66: CAJA (24UD) RETORN LATAS GATO ATUN CON GAMBAS 80 GR | F66: Humedo | G66: Gato | H66: Gambas | I66: 653 | J66: https://retorn.com/products/comida-humeda-para-gatos-atun-gambas?variant=48155011350867
A67: 12632940478530 | B67: 8436540361547 | C67: 185 gr | E67: RETORN LATAS PERRO CORDERO CON ARROZ 185 GR | F67: Humedo | G67: Perro | H67: Cordero Arroz | I67: 896 | J67: https://retorn.com/products/comida-humeda-perros-cordero-arroz?variant=12632940478530
A68: 14250706075714 | C68: 185 gr x 12ud | D68: RET479801E | E68: RETORN LATAS PERRO CORDERO CON ARROZ 185 GR | F68: Humedo | G68: Perro | H68: Cordero Arroz | I68: 896 | J68: https://retorn.com/products/comida-humeda-perros-cordero-arroz?variant=14250706075714
A69: 14102309306434 | B69: 8436540361127 | C69: 400 gr | E69: RETORN LATAS PERRO CORDERO CON ARROZ 400 GR | F69: Humedo | G69: Perro | H69: Cordero Arroz | I69: 896 | J69: https://retorn.com/products/comida-humeda-perros-cordero-arroz?variant=14102309306434
A70: 14250709057602 | C70: 400 gr x 12ud | D70: RET4798014E | E70: RETORN LATAS PERRO CORDERO CON ARROZ 400 GR | F70: Humedo | G70: Perro | H70: Cordero Arroz | I70: 896 | J70: https://retorn.com/products/comida-humeda-perros-cordero-arroz?variant=14250709057602
A71: 13839214772290 | B71: 8436540361493 | C71: 185 gr | E71: RETORN LATAS PERRO ONLY CORDERO 185 GR | F71: Humedo | G71: Perro | H71: Only Cordero | I71: 920 | J71: https://retorn.com/products/comida-humeda-perros-only-cordero?variant=13839214772290
A72: 14250754048066 | C72: 185 gr x 12ud | D72: RET479805E | E72: RETORN LATAS PERRO ONLY CORDERO 185 GR | F72: Humedo | G72: Perro | H72: Only Cordero | I72: 920 | J72: https://retorn.com/products/comida-humeda-perros-only-cordero?variant=14250754048066
A73: 15962371194946 | B73: 8436540361097 | C73: 400 gr | E73: RETORN LATAS PERRO ONLY CORDERO 400 GR | F73: Humedo | G73: Perro | H73: Only Cordero | I73: 920 | J73: https://retorn.com/products/comida-humeda-perros-only-cordero?variant=15962371194946
A74: 15982942421058 | C74: 400 gr x 12ud | D74: RET4798054 | E74: RETORN LATAS PERRO ONLY CORDERO 400 GR | F74: Humedo | G74: Perro | H74: Only Cordero | I74: 920 | J74: https://retorn.com/products/comida-humeda-perros-only-cordero?variant=15982942421058
A75: 37988511940791 | B75: 8436540360373 | C75: 185 gr | E75: RETORN LATAS PERRO POLLO CON ZANAHORIAS 185 GR | F75: Humedo | G75: Perro | H75: Pollo Zanahoria | I75: 854 | J75: https://retorn.com/products/comida-humeda-perros-pollo-zanahorias?variant=37988511940791
A76: 37988515152055 | C76: 185 gr x 12ud | D76: RET479803E | E76: RETORN LATAS PERRO POLLO CON ZANAHORIAS 185 GR | F76: Humedo | G76: Perro | H76: Pollo Zanahoria | I76: 854 | J76: https://retorn.com/products/comida-humeda-perros-pollo-zanahorias?variant=37988515152055
A77: 14102317400130 | B77: 8436540361110 | C77: 400 gr | E77: RETORN LATAS PERRO POLLO CON ZANAHORIAS 400 GR | F77: Humedo | G77: Perro | H77: Pollo Zanahoria | I77: 854 | J77: https://retorn.com/products/comida-humeda-perros-pollo-zanahorias?variant=14102317400130
A78: 14250742546498 | C78: 400 gr x 12ud | D78: RET4798034E | E78: RETORN LATAS PERRO POLLO CON ZANAHORIAS 400 GR | F78: Humedo | G78: Perro | H78: Pollo Zanahoria | I78: 854 | J78: https://retorn.com/products/comida-humeda-perros-pollo-zanahorias?variant=14250742546498
...

Sheet Razas
B4: Razas pequeñas | C4: Razas Medianas | D4: Razas grandes
B5: Pomerania (Spitz enano) | C5: Scottish terrier | D5: Pastor alemán
B6: Bichón maltés | C6: Basenji | D6: Pastor Bergamasco
B7: Grifón de Bruselas | C7: Cocker spaniel americano | D7: Akita Inu
B8: Chihuahua | C8: Terrier irlandés | D8: Alaskan malamute
B9: Toy spaniel inglés | C9: Spitz alemán Estándar | D9: Pastor de Brie
B10: Yorkshire terrier | C10: Spitz finlandés | D10: Retriever de pelo liso
B11: Silky terrier (australiano) | C11: Grifón vendeano | D11: Boyero de Flandes
B12: Pequinés | C12: Skye terrier | D12: Leonberger
B13: Pinscher | C13: Beagle | D13: Dogo de Burdeos (mediano)
B14: Shih Tzu | C14: Saluki | D14: Rottweiler
B15: Bichón frisé | C15: Whippet | D15: Fila brasileño
... B33: Boston terrier | C33: Braco húngaro / Vizsla | D33: Mestizo de raza grande
B34: Terrier galés (Welsh) | C34: Chow Chow
B35: Mestizo de raza pequeña | C35: Perdiguero alemán
C36: Podenco ibicenco
C37: Husky siberiano
C38: Dálmata
C39: Bulldog
C40: Galgo afgano
C41: Grifón de pelo duro
C42: Perro de agua portugués
C43: Bull terrier
C44: Boxer
C45: Bobtail
C46: Samoyedo
C47: Braco francés
... C65: Mestizo de raza mediana

Sheet Formula Final Calculo
E5: Formula Final Perros
E6: Valores | G6: SECO | I6: MIXTO g/dia
E7: Producto | F7: Kcal Necesarias / Día | G7: Gr Producto / día / Seco | I7: SECO 75% | J7: HÚMEDO 25%
E8: Puppy + PUPPY | F8: ='Formula Perros'!H11 -> 2479.3522 | G8: =F8/Productos!I9*1000 -> 718.44456 | I8: =((F8*75)/100)/Productos!I9*1000 -> 538.83342 | J8: =((F8*25)/100)/Productos!I89*1000 -> 489.99055
E9: Cordero + CORDERO ARROZ | G9: =F8/Productos!I21*1000 -> 720.74191 | I9: =((F8*75)/100)/Productos!I21*1000 -> 540.55643 | J9: =((F8*25)/100)/Productos!I68*1000 -> 691.78353
E10: Pollo + POLLO ZANAHORIA | G10: =F8/Productos!I16*1000 -> 674.83728 | I10: =((F8*75)/100)/Productos!I16*1000 -> 506.12796 | J10: =((F8*25)/100)/Productos!I77*1000 -> 725.80567
E11: Salmón + PESCADO ZANAHORIA | G11: =F8/Productos!I33*1000 -> 745.22157 | I11: =((F8*75)/100)/Productos!I33*1000 -> 558.91618 | J11: =((F8*25)/100)/Productos!I84*1000 -> 568.65876
E12: Light + PESCADO ZANAHORIA | G12: =F8/Productos!I13*1000 -> 718.02843 | I12: =((F8*75)/100)/Productos!I13*1000 -> 538.52132 | J12: =((F8*25)/100)/Productos!I84*1000 -> 568.65876
G15: =F8/Productos!I86*1000 -> 2274.635
E21: Formula Final Gatos
E22: Valores | G22: SECO | I22: MIXTO g/dia
E23: Producto | F23: Kcal Necesarias / Día | G23: Gr Producto / día | I23: SECO 75% | J23: HUMEDO 25% segons sabor
E24: Pollo + POLLO CON CONEJO | F24: ='Formula Gatos'!I11 -> 159.1073 | G24: =F24/Productos!I38*1000 -> 39.092702 | I24: =((F24*75)/100)/Productos!I38*1000 -> 29.319526 | J24: =((F24*25)/100)/Productos!I53*1000 -> 42.18115
E25: Pescado + ATÚN CON GAMBAS | G25: =F24/Productos!I36*1000 -> 43.1653 | I25: =((F24*75)/100)/Productos!I36*1000 -> 32.373975 | J25: =((F24*25)/100)/Productos!I64*1000 -> 60.913973
E26: Esterilizado + POLLO | G26: =F24/Productos!I41*1000 -> 40.382563 | I26: =((F24*75)/100)/Productos!I41*1000 -> 30.286922 | J26: =((F24*25)/100)/Productos!I50*1000 -> 40.964803
E27: Kitten + KITTEN | G27: =F24/Productos!I44*1000 -> 38.127797 | I27: =((F24*75)/100)/Productos!I44*1000 -> 28.595848 | J27: =((F24*25)/100)/Productos!I48*1000 -> 45.667996
